Workbook

Sheet Assumptions
B2: Scenario Toggle | E2: =MATCH(C4,C11:C13,0) -> 2
C4: Base | D4: ¬Select cell to change Scenario
B5: Current Scenario
B7: Scenario Helper Table
C9: Scenario | D9: LFL rate | E9: NSO | F9: G&A Expense | G9: PPE Capex
D10: Percentages below are % of Revenue
B11: 1 | C11: Bear | D11: 0.03 | E11: 110 | F11: 0.085 | G11: 0.04
B12: 2 | C12: Base | D12: 0.04 | E12: 125 | F12: 0.07 | G12: 0.045
B13: 3 | C13: Bull | D13: 0.05 | E13: 140 | F13: 0.065 | G13: 0.05
B15: Assumptions
B16: Variable | H16: Fiscal Years Ending December 31, | P16: Source (Full Methodology in Appendix) | Q16: [1]
B17: All figures in $ 000s unless stated | H17: 2024 | I17: 2025 | J17: 2026 | K17: 2027 | L17: 2028 | M17: 2029 | N17: 2030
B19: Revenue Drivers
B20: NSO (Organic) (# of stores) | H20: 155 | I20: 113 | J20: =(INDEX(Assumptions!$B$11:$E$13,Assumptions!$E$2,4))-J22 -> 115 | K20: =INDEX(Assumptions!$B$11:$E$13,Assumptions!$E$2,4) -> 125 | L20: =INDEX(Assumptions!$B$11:$E$13,Assumptions!$E$2,4) -> 125 | M20: =INDEX(Assumptions!$B$11:$E$13,Assumptions!$E$2,4) -> 125 | N20: =INDEX(Assumptions!$B$11:$E$13,Assumptions!$E$2,4) -> 125 | P20: Scenario toggle; base 125, bear 110, bull 140
B21: LfL growth (% of revenue) | H21: -0.125 | I21: 0.097 | J21: =INDEX(Assumptions!$B$11:$E$13,Assumptions!$E$2,3) -> 0.04 | K21: =INDEX(Assumptions!$B$11:$E$13,Assumptions!$E$2,3) -> 0.04 | L21: =INDEX(Assumptions!$B$11:$E$13,Assumptions!$E$2,3) -> 0.04 | M21: =INDEX(Assumptions!$B$11:$E$13,Assumptions!$E$2,3) -> 0.04 | N21: =INDEX(Assumptions!$B$11:$E$13,Assumptions!$E$2,3) -> 0.04 | P21: Scenario toggle; base 5.0%, bear 4.0%, bull 6.0%
B22: Stores Acquired (# of stores) | H22: 0 | I22: 46 | J22: 10 | K22: 0 | L22: 0 | M22: 0 | N22: 0 | P22: Actuals only; zero from 2026
B23: Total number of Stores | H23: 2590 | I23: =H23+I20+I22 -> 2749 | J23: =I23+J20+J22 -> 2874 | K23: =J23+K20+K22 -> 2999 | L23: =K23+L20+L22 -> 3124 | M23: =L23+M20+M22 -> 3249 | N23: =M23+N20+N22 -> 3374
B24: Revenue per Store | H24: ='3- Statement Model'!$C$6/H23 -> 848.16641 | I24: ='3- Statement Model'!$D$6/I23 -> 912.63041 | J24: =(I24*(1+J21)) -> 949.13563 | K24: =(J24*(1+K21)) -> 987.10105 | L24: =(K24*(1+L21)) -> 1026.5851 | M24: =(L24*(1+M21)) -> 1067.6485 | N24: =(M24*(1+N21)) -> 1110.3544
B26: Operating Expenses
B27: COGS (% of revenue) | H27: =-'3- Statement Model'!$C$7/'3- Statement Model'!$C$6 -> 0.42452467 | I27: =-'3- Statement Model'!D7/'3- Statement Model'!D6 -> 0.41337704 | J27: 0.41 | K27: 0.41 | L27: 0.41 | M27: 0.41 | N27: 0.41 | P27: Slight improvement from 2025 actual (41.3%)
B28: S&A Expense (% of revenue) | H28: =-'3- Statement Model'!$C$10/'3- Statement Model'!$C$6 -> 0.28619903 | I28: =-'3- Statement Model'!$D$10/'3- Statement Model'!$D$6 -> 0.2849159 | J28: 0.285 | K28: 0.285 | L28: 0.285 | M28: 0.285 | N28: 0.285 | P28: 2-yr avg (2024: 28.62%; 2025: 28.49%)
B29: G&A Expense (% of revenue) | H29: =-'3- Statement Model'!$C$11/'3- Statement Model'!$C$6 -> 0.072547594 | I29: =-'3- Statement Model'!$D$11/'3- Statement Model'!$D$6 -> 0.069209402 | J29: =INDEX(Assumptions!$B$11:$F$13,Assumptions!$E$2,5) -> 0.07 | K29: =INDEX(Assumptions!$B$11:$F$13,Assumptions!$E$2,5) -> 0.07 | L29: =INDEX(Assumptions!$B$11:$F$13,Assumptions!$E$2,5) -> 0.07 | M29: =INDEX(Assumptions!$B$11:$F$13,Assumptions!$E$2,5) -> 0.07 | N29: =INDEX(Assumptions!$B$11:$F$13,Assumptions!$E$2,5) -> 0.07 | P29: Scenario toggle; base 7.0%, bear 7.5%, bull 6.5%
B30: EBITDA Margin (% of revenue) | H30: =1-(H27+H28+H29) -> 0.21672871 | I30: =1-(I27+I28+I29) -> 0.23249766 | J30: =1-(J27+J28+J29) -> 0.235 | K30: =1-(K27+K28+K29) -> 0.235 | L30: =1-(L27+L28+L29) -> 0.235 | M30: =1-(M27+M28+M29) -> 0.235 | N30: =1-(N27+N28+N29) -> 0.235 | P30: Plug; base 23.5%, bear 23.0%, bull 24.0%
B32: Financing and Tax
B33: Finance Income [LBO] | H33: 16116 | I33: 15508 | J33: 0 | K33: 0 | L33: 0 | M33: 0 | N33: 0 | P33: Zero - cash swept at LBO entry
B34: Finance Income (% of opening cash) [Hold Listed Scenario] | H34: 0.056 | I34: 0.0435 | J34: 0.04 | K34: 0.04 | L34: 0.04 | M34: 0.04 | N34: 0.04 | P34: 4.0% on opening cash - below 2-yr avg (4.98%) | Q34: [2]
B35: Lease Finance Costs (% of average lease balance) | H35: =-'3- Statement Model'!C$27/(('3- Statement Model'!C180+'3- Statement Model'!$C$185)/2) -> 0.059518625 | I35: =-('3- Statement Model'!D$27)/(('3- Statement Model'!D180+'3- Statement Model'!$D$185)/2) -> 0.067199048 | J35: 0.063 | K35: 0.063 | L35: 0.063 | M35: 0.063 | N35: 0.063 | P35: 6.3% - 3-yr avg adjusted upward for IBR increases
B36: Non-Lease Finance Costs | H36: 148 | I36: 42 | J36: 42 | K36: 42 | L36: 42 | M36: 42 | N36: 42 | P36: Frozen at 2025 actual ($42k) - bank charges only
P37: In the P&L, this also includes EOSB Interest
B38: Effective Income Tax Rate (% of PBT) | H38: =-'3- Statement Model'!C30/'3- Statement Model'!C28 -> 0.1204141 | I38: =-'3- Statement Model'!D30/'3- Statement Model'!D28 -> 0.14030248 | J38: 0.16 | K38: 0.16 | L38: 0.16 | M38: 0.16 | N38: 0.16 | P38: 16% - Pillar 2 full implementation
P39: Tax paid assumed equal to the full income tax charge
B41: Working Capital
B42: Inventory
B43: Inventory Days | H43: =-'3- Statement Model'!C51/'3- Statement Model'!C7*365 -> 52.602348 | I43: =-'3- Statement Model'!D51/'3- Statement Model'!D7*365 -> 54.579887 | J43: 54 | K43: 54 | L43: 54 | M43: 54 | N43: 54 | P43: Anchored to 2025 actual (54.6 days)
B45: Trade and Other Receivables
B46: AR Days | H46: ='3- Statement Model'!C212/'3- Statement Model'!C6*365 -> 5.7459539 | I46: ='3- Statement Model'!D212/'3- Statement Model'!D6*365 -> 7.5152592 | J46: 7.5 | K46: 7.5 | L46: 7.5 | M46: 7.5 | N46: 7.5 | P46: Anchored to 2025 actual (7.5 days)
B47: Prepaid Expenses (% of revenue) | H47: 0.0165 | I47: 0.0151 | J47: 0.015 | K47: 0.015 | L47: 0.015 | M47: 0.015 | N47: 0.015 | P47: 3-yr avg 1.61% (2023-2025); rounded to 1.5%
B48: Advances to Suppliers | H48: 2320 | I48: 1612 | J48: 1612 | K48: 1612 | L48: 1612 | M48: 1612 | N48: 1612 | P48: Frozen at 2025 actual ($1,612k) - immaterial
B49: Refundable Deposits | H49: 15373 | I49: 16100 | J49: 16100 | K49: 16100 | L49: 16100 | M49: 16100 | N49: 16100 | P49: Frozen at 2025 actual ($16,100k)
B50: Accrued income (% of revenue) | H50: ='3- Statement Model'!C216/'3- Statement Model'!C6 -> 0.006326616 | I50: ='3- Statement Model'!D216/'3- Statement Model'!D6 -> 0.0061367471 | J50: 0.006 | K50: 0.006 | L50: 0.006 | M50: 0.006 | N50: 0.006 | P50: 3-yr avg 0.59% (2023-2025); rounded to 0.6%
...

Sheet 3- Statement Model
B2: Income Statement
E3: Fiscal Years Ending December 31,
B4: ($ in 000s) | C4: 2024 | D4: 2025 | E4: 2026 | F4: 2027 | G4: 2028 | H4: 2029 | I4: 2030
B6: Revenue | C6: 2196751 | D6: 2508821 | E6: =Assumptions!J23*Assumptions!J24 -> 2727815.8 | F6: =Assumptions!K23*Assumptions!K24 -> 2960316.1 | G6: =Assumptions!L23*Assumptions!L24 -> 3207051.8 | H6: =Assumptions!M23*Assumptions!M24 -> 3468790 | I6: =Assumptions!N23*Assumptions!N24 -> 3746335.9 | K6: =I6/D6 -> 1.4932655 | L6: =K6^(1/5) -> 1.0834962
B7: COGS | C7: =-1029357+96782 -> -932575 | D7: =-1143928+106839 -> -1037089 | E7: =-E6*Assumptions!J27 -> -1118404.5 | F7: =-F6*Assumptions!K27 -> -1213729.6 | G7: =-G6*Assumptions!L27 -> -1314891.3 | H7: =-H6*Assumptions!M27 -> -1422203.9 | I7: =-I6*Assumptions!N27 -> -1535997.7
B8: Gross Profit | C8: =C6+C7 -> 1264176 | D8: =D6+D7 -> 1471732 | E8: =E6+E7 -> 1609411.3 | F8: =F6+F7 -> 1746586.5 | G8: =G6+G7 -> 1892160.6 | H8: =H6+H7 -> 2046586.1 | I8: =I6+I7 -> 2210338.2
B10: S&A Expense | C10: =-784704+155996 -> -628708 | D10: =-886102+171299 -> -714803 | E10: =-E6*Assumptions!J28 -> -777427.5 | F10: =-F6*Assumptions!K28 -> -843690.08 | G10: =-G6*Assumptions!L28 -> -914009.77 | H10: =-H6*Assumptions!M28 -> -988605.14 | I10: =-I6*Assumptions!N28 -> -1067705.7
B11: G&A Expense | C11: =-184744+25375 -> -159369 | D11: =-202562+28928 -> -173634 | E11: =-E6*Assumptions!J29 -> -190947.11 | F11: =-F6*Assumptions!K29 -> -207222.12 | G11: =-G6*Assumptions!L29 -> -224493.63 | H11: =-H6*Assumptions!M29 -> -242815.3 | I11: =-I6*Assumptions!N29 -> -262243.51
B12: Other Income | C12: 7461 | D12: 13361 | E12: =-E105 -> -2983 | F12: =-F105 -> -2983 | G12: =-G105 -> -2983 | H12: =-H105 -> -2983 | I12: =-I105 -> -2983 | J12: [3]
B13: Loss/Gain due to Hyperinflation | C13: 125 | D13: -1052 | E13: 0 | F13: 0 | G13: 0 | H13: 0 | I13: 0
B14: EBITDA | C14: =C8+C10+C11+C12+C13 -> 483685 | D14: =D8+D10+D11+D12+D13 -> 595604 | E14: =E8+E10+E11+E12+E13 -> 638053.71 | F14: =F8+F10+F11+F12+F13 -> 692691.27 | G14: =G8+G10+G11+G12+G13 -> 750674.18 | H14: =H8+H10+H11+H12+H13 -> 812182.64 | I14: =I8+I10+I11+I12+I13 -> 877405.93
B16: D&A | C16: -278153 | D16: -307066 | E16: =E17+E18 -> -321555.06 | F16: =F17+F18 -> -331130.6 | G16: =G17+G18 -> -348295.37 | H16: =H17+H18 -> -363425.07 | I16: =I17+I18 -> -377536.96
B17: Non-RoU Assets | C17: =C160+C196-195 -> -94343 | D17: =D160+D196-167 -> -101500 | E17: =E160+E196+E203 -> -101659.14 | F17: =F160+F196+F203 -> -110181.65 | G17: =G160+G196+G203 -> -119472.48 | H17: =H160+H196+H203 -> -129562.86 | I17: =I160+I196+I203 -> -140449.58
B18: RoU Assets | C18: =C$171 -> -183810 | D18: =D$171 -> -205566 | E18: =E$171 -> -219895.92 | F18: =F$171 -> -220948.95 | G18: =G$171 -> -228822.89 | H18: =H$171 -> -233862.21 | I18: =I$171 -> -237087.37
B19: EBIT | C19: =C14+C16 -> 205532 | D19: =D14+D16 -> 288538 | E19: =E14+E16 -> 316498.65 | F19: =F14+F16 -> 361560.67 | G19: =G14+G16 -> 402378.81 | H19: =H14+H16 -> 448757.57 | I19: =I14+I16 -> 499868.97
B21: Impairment losses | C21: =-12631-1093 -> -13724 | D21: =-5559-251 -> -5810 | E21: 0 | F21: 0 | G21: 0 | H21: 0 | I21: 0
B22: Operating Profit | C22: =SUM(C19:C21) -> 191808 | D22: =SUM(D19:D21) -> 282728 | E22: =SUM(E19:E21) -> 316498.65 | F22: =SUM(F19:F21) -> 361560.67 | G22: =SUM(G19:G21) -> 402378.81 | H22: =SUM(H19:H21) -> 448757.57 | I22: =SUM(I19:I21) -> 499868.97
B24: Finance Income | C24: 16116 | D24: 15508 | E24: =Assumptions!J33 -> 0 | F24: =Assumptions!K33 -> 0 | G24: =Assumptions!L33 -> 0 | H24: =Assumptions!M33 -> 0 | I24: =Assumptions!N33 -> 0
B25: Finance Costs | C25: -35793 | D25: -44135 | E25: =E26+E27 -> -43476.447 | F25: =F26+F27 -> -44139.935 | G25: =G26+G27 -> -45241.624 | H25: =H26+H27 -> -45999.432 | I25: =I26+I27 -> -46535.048
B26: Non Lease Finance Costs | C26: =-3326-148 -> -3474 | D26: =-3226-42 -> -3268 | E26: =-(Assumptions!J36+'3- Statement Model'!E231) -> -3359.9405 | F26: =-(Assumptions!K36+'3- Statement Model'!F231) -> -3465.7828 | G26: =-(Assumptions!L36+'3- Statement Model'!G231) -> -3575.0015 | H26: =-(Assumptions!M36+'3- Statement Model'!H231) -> -3687.7042 | I26: =-(Assumptions!N36+'3- Statement Model'!I231) -> -3804.0022
B27: Lease Finance Costs | C27: -32319 | D27: -40867 | E27: =-((E180+E185)/2)*Assumptions!J35 -> -40116.507 | F27: =-((F180+F185)/2)*Assumptions!K35 -> -40674.152 | G27: =-((G180+G185)/2)*Assumptions!L35 -> -41666.622 | H27: =-((H180+H185)/2)*Assumptions!M35 -> -42311.727 | I27: =-((I180+I185)/2)*Assumptions!N35 -> -42731.046
B28: Profit before Tax | C28: =C22+C24+C25 -> 172131 | D28: =D22+D24+D25 -> 254101 | E28: =E22+E24+E25 -> 273022.2 | F28: =F22+F24+F25 -> 317420.74 | G28: =G22+G24+G25 -> 357137.19 | H28: =H22+H24+H25 -> 402758.14 | I28: =I22+I24+I25 -> 453333.93
B30: Income taxes and Zakat | C30: -20727 | D30: -35651 | E30: =-E28*Assumptions!J38 -> -43683.552 | F30: =-F28*Assumptions!K38 -> -50787.318 | G30: =-G28*Assumptions!L38 -> -57141.95 | H30: =-H28*Assumptions!M38 -> -64441.303 | I30: =-I28*Assumptions!N38 -> -72533.428
B31: Net Profit | C31: =C28+C30 -> 151404 | D31: =D28+D30 -> 218450 | E31: =E28+E30 -> 229338.65 | F31: =F28+F30 -> 266633.42 | G31: =G28+G30 -> 299995.24 | H31: =H28+H30 -> 338316.84 | I31: =I28+I30 -> 380800.5
C32: =C31/C6 -> 0.068921785 | D32: =D31/D6 -> 0.087072772 | E32: =E31/E6 -> 0.084074096 | F32: =F31/F6 -> 0.09006924 | G32: =G31/G6 -> 0.093542373 | H32: =H31/H6 -> 0.097531659 | I32: =I31/I6 -> 0.10164612
B34: Balance Sheet
E35: Fiscal Years Ending December 31,
B36: ($ in 000s) | C36: =C$4 -> 2024 | D36: =D$4 -> 2025 | E36: =E$4 -> 2026 | F36: =F$4 -> 2027 | G36: =G$4 -> 2028 | H36: =H$4 -> 2029 | I36: =I$4 -> 2030
B38: ASSETS
B40: Non-Current Assets
B41: Property and Equipment | C41: 328761 | D41: 341405 | E41: =E163 -> 372700.41 | F41: =F163 -> 406321.53 | G41: =G163 -> 442304.26 | H41: =H163 -> 480709.7 | I41: =I163 -> 521619.29
B42: Right of Use Assets | C42: 566054 | D42: 610822 | E42: =E174 -> 613747.08 | F42: =F174 -> 635619.13 | G42: =G174 -> 649617.24 | H42: =H174 -> 658576.04 | I42: =I174 -> 664309.66
B43: Investment Property | C43: 3356 | D43: 3712 | E43: =Assumptions!J77 -> 3712 | F43: =Assumptions!K77 -> 3712 | G43: =Assumptions!L77 -> 3712 | H43: =Assumptions!M77 -> 3712 | I43: =Assumptions!N77 -> 3712
B44: Intangibles | C44: 59201 | D44: 63312 | E44: =E206 -> 85623.05 | F44: =F206 -> 88113.4 | G44: =G206 -> 91534.827 | H44: =H206 -> 95791.814 | I44: =I206 -> 100812.77
B45: Trade and other Receivables | C45: 7498 | D45: 10784 | E45: =E223 -> 7500 | F45: =F223 -> 7500 | G45: =G223 -> 7500 | H45: =H223 -> 7500 | I45: =I223 -> 7500
B46: Long term Deposits with Banks | C46: 0 | D46: 117838 | E46: 0 | F46: 0 | G46: 0 | H46: 0 | I46: 0 | J46: [4]
B47: Deferred Tax Asset | C47: 2280 | D47: 3594 | E47: =Assumptions!J89 -> 3594 | F47: =Assumptions!K89 -> 3594 | G47: =Assumptions!L89 -> 3594 | H47: =Assumptions!M89 -> 3594 | I47: =Assumptions!N89 -> 3594
B48: Non-Current Assets | C48: =SUM(C41:C47) -> 967150 | D48: =SUM(D41:D47) -> 1151467 | E48: =SUM(E41:E47) -> 1086876.5 | F48: =SUM(F41:F47) -> 1144860.1 | G48: =SUM(G41:G47) -> 1198262.3 | H48: =SUM(H41:H47) -> 1249883.6 | I48: =SUM(I41:I47) -> 1301547.7
B50: Current Assets
B51: Inventories | C51: 134399 | D51: 155080 | E51: =-E7*Assumptions!J43/365 -> 165462.58 | F51: =-F7*Assumptions!K43/365 -> 179565.47 | G51: =-G7*Assumptions!L43/365 -> 194531.86 | H51: =-H7*Assumptions!M43/365 -> 210408.25 | I51: =-I7*Assumptions!N43/365 -> 227243.5
...

Sheet LBO Model
B2: Sources and Uses - Americana Restaurants LBO
B4: Assumptions
B5: Current Share Price in AED | C5: 1.87 | D5: 46131
B6: Tender Price in AED (ex-dividend) | C6: ='Returns Analysis - LBO'!C17 -> 2.5318601
B7: AED/USD exchange rate | C7: 3.6725
B8: Shares Outstanding | C8: 8398633100
B9: Adeptio current ownership | C9: 0.6603
B10: Float to be acquired | C10: =100%-C9 -> 0.3397
B11: Max. Total Debt/EBITDA | C11: 4
B12: Lease/EBITDA | C12: ='3- Statement Model'!D185/'3- Statement Model'!D14 -> 1.070285
B13: Max LBO Debt/EBITDA | C13: =C11-C12 -> 2.929715
B14: Transaction costs | C14: 0.02
B15: Interest rate | C15: 0.085
B16: Annual amortisation rate | C16: 0.01
B17: Min. operating cash retained ($ 000s) | C17: 80000
B18: FY25 EBITDA (actuals in $ 000s) | C18: =('3- Statement Model'!D14) -> 595604
B19: FY26 EBITDA (projected in $ 000s) | C19: ='3- Statement Model'!E14 -> 638053.71
B20: Tax Rate | C20: =Assumptions!J38 -> 0.16
B22: Derived Calculations
B23: Tender price in USD (cum-dividend) | C23: ='Returns Analysis - LBO'!C15/$C$7 -> 0.71341048
B24: Dividend per share in USD (paid in 2026 pre LBO close) | C24: =-'LBO Model'!C41*1000/'LBO Model'!C8 -> 0.023999977
B25: Share Price Ex-dividend | C25: =C23-C24 -> 0.68941051
B26: Float shares to acquire | C26: =$C$8*$C$10 -> 2.8530157e+09
B27: Float acquisition cost ($ 000s) | C27: =$C$26*$C$25/1000 -> 1966899
B28: Transaction costs ($ 000s) | C28: =C27*C14 -> 39337.979
B29: Total gross LBO debt drawable ($ 000s) | C29: =C18*C13 -> 1744950
B30: Net LBO debt drawn ($ 000s) | C30: =MAX(MIN(C29,C27+C28-C45),0) -> 1744950
B31: Adeptio equity required ($ 000s) | C31: =MAX(C27+C28-C30-C45,0) -> 125443.95
B33: Cash Reconciliation - 2025 Closing Balance to LBO Close
C34: ($ in 000s)
B35: ST Deposits available | C35: ='3- Statement Model'!D54 -> 145235
B36: LT Deposits available | C36: ='3- Statement Model'!D46 -> 117838
B37: Cash Balance Available | C37: ='3- Statement Model'!D55 -> 154337
B38: Minimum Cash Balance | C38: =C17 -> 80000
B39: Excess operating cash | C39: =C37-C38 -> 74337
B40: Total cash available | C40: =C35+C36+C39 -> 337410
B41: (-) Dividend payment in 2026 (Pre-LBO close) | C41: =-Assumptions!J104 -> -201567 | D41: [12]
B42: from Cash | C42: =-(MIN(C39,-C41)) -> -74337
B43: from ST Deposits | C43: =-MIN(C35,-(C41-C42)) -> -127230
B44: from LT Deposits | C44: =-MIN(C36,-(C41-C42-C43)) -> 0
...

Sheet Returns Analysis - LBO
D1: v3.0 April 2026
B2: Returns Analysis - Americana Restaurants LBO
B4: Entry Assumptions
B5: Entry EV ($ 000s) | C5: ='LBO Model'!C68 -> 6211728.9
B6: Entry EBITDA - 2025 ($ 000s) | C6: ='LBO Model'!C18 -> 595604
B7: Entry EV/EBITDA | C7: =C5/C6 -> 10.429293
B8: LBO Debt at Entry ($ 000s) | C8: ='LBO Model'!C30 -> 1744950
B9: Excess cash swept at LBO Entry | C9: ='LBO Model'!C45 -> 135843
B10: Adeptio Equity contribution ($ 000s) | C10: ='LBO Model'!C31 -> 125443.95
B11: Adeptio Initial acquisition equity cost (Oct 2016) ($ 000s) | C11: 850000 | D11: [13]
B12: Adeptio MTO equity cost (Jan 2017) ($ 000s) | C12: 1020000 | D12: [14]
B13: IPO Proceeds (Dec 2022) | C13: 1800000 | D13: [15]
B14: Adeptio Existing Stake | C14: ='LBO Model'!C9 -> 0.6603
B15: Offer price (total consideration) | C15: 2.62 | D15: [16]
B16: Dividend per share in AED (paid pre-close) | C16: =-'LBO Model'!C41*1000*'LBO Model'!C7/'LBO Model'!C8 -> 0.088139915
B17: Tender Price in AED (ex-dividend) | C17: =C15-C16 -> 2.5318601
B18: Tender Premium to market | C18: =(C17-('LBO Model'!C5-C16))/('LBO Model'!C5-C16) -> 0.42090847
B20: Exit Assumptions
B21: Exit year | C21: 2030
B22: Growth rate scenario | C22: =IFERROR(CHOOSE(Assumptions!E2,"Bear","Base","Bull"),"Base") -> Base
B23: Exit EBITDA ($ 000s) | C23: ='3- Statement Model'!I14 -> 877405.93
B24: Exit EV/EBITDA ($ 000s) | C24: 8.09
B25: LBO Debt at exit ($ 000s) | C25: ='LBO Model'!C102 -> 868528.56
B26: Lease Liabilitiies at exit ($ 000s) | C26: ='3- Statement Model'!I185 -> 680892.57
B27: Minimum Cash Retained ($ 000s) | C27: ='LBO Model'!C17 -> 80000
B29: Incremental IRR Returns - LBO vs Hold Listed
B31: Incremental IRR | C31: =XIRR(F98:F103,C98:C103,) -> 0.065586129
B33: Entry and Exit Equity Value Summary
C34: ($ in 000s)
B36: Entry EV | C36: ='LBO Model'!C68 -> 6211728.9
B37: (-) Lease Liabilities at entry | C37: =-'3- Statement Model'!E180 -> -637466
B38: (+) Cash at entry | C38: =SUM('LBO Model'!C48:C50) -> 215843
B39: Implied Opening Equity | C39: =C36+C37+C38 -> 5790105.9
B40: Adeptio's stake in Opening Equity | C40: =C39*'LBO Model'!C9 -> 3823206.9
B41: Equity investment at LBO entry | C41: =C10 -> 125443.95
B42: Equity Base at LBO entry | C42: =C40+C41 -> 3948650.9
B44: Exit EV | C44: =C24*C23 -> 7098214
B45: (-) LBO Debt at exit | C45: =-'LBO Model'!G87 -> -868528.56
B46: (-) Lease Liabilities at exit | C46: =-'3- Statement Model'!I185 -> -680892.57
B47: (+) Cash at exit | C47: =C27 -> 80000
...

Sheet Appendix - Footnotes
C2: Appendix - Footnotes
B4: [1] | C4: Methodology behind Model assumptions
C6: Section | D6: Variable | E6: Basis (Short Note) | F6: Full Methodology
C7: Americana Restaurants LBO Model | All figures in USD 000s unless stated | March 2026
C8: Revenue Drivers
C9: Revenue Drivers | D9: NSO (Organic) | E9: Scenario toggle; base 125, bear 110, bull 140 | F9: Base case of 125 NSOs per annum, in line with the midpoint of management guidance of 120-130. Bear: 110 (below guidance, stress scenario reflecting potential slowdown in expansion); Bull: 140 (above guidance, reflecting accelerated rollout) Management guidance has in the past included acquired stores as a part of NSOs as well, the same methodology has been assumed for 2026
C10: Revenue Drivers | D10: LfL Growth | E10: Scenario toggle; base 4.0%, bear 3.0%, bull 5.0% | F10: Base case of 4.0%, representing the lower end of management guidance of mid single digits (4-6%). Bear: 3.0% (below guidance); Bull: 5.0% (management guidance). 2024 actual of -12.5% and 2025 actual of 9.7% excluded as distorted by regional geopolitical headwinds and subsequent normalisation
C11: Revenue Drivers | D11: Stores Acquired | E11: Actuals only; zero from 2027 | F11: 2025-Pizza Hut Oman; 2026-MAT. Note: MAT stores assumed to reach similar operational efficiency and sales per store levels as the existing stores for simplicity reasons. Current revenue per store for MAT is $2.1m
C12: Operating Expenses
C13: Operating Expenses | D13: COGS (% of Revenue) | E13: Slight improvement from 2025 actual (41.3%) | F13: Slight improvement from the 2025 actual of 41.3% (2024: 42.5%), reflecting management guidance on inventory cost savings through menu reengineering and supplier negotiations. 2022/2023 excluded (2022: 48.3%; 2023: 47.7%) as unrepresentative, reflecting elevated global food commodity prices
C14: Operating Expenses | D14: S&A Expense (% of Revenue) | E14: 2-yr avg (2024: 28.62%; 2025: 28.49%) | F14: Held at the 2-year average of 28.56% (2024: 28.62%; 2025: 28.49%), rounded to 28.5%. 2022/2023 excluded (2022: 31.07%; 2023: 32.21%) as unrepresentative of the current cost structure
C15: Operating Expenses | D15: G&A Expense (% of Revenue) | E15: Scenario toggle; base 7.0%, bear 8.5%, bull 6.5% | F15: Scenario toggle reflecting operating leverage and management guidance on G&A reduction through restructuring and offshoring of low-value-add roles (2022: 8.12%; 2023: 7.95%; 2024: 7.26%; 2025: 6.93%). Bear: 8.5% stress assumption reflecting inability to reduce/worsening of fixed G&A costs in a weaker revenue environment. Base: 7.0% modest improvement from 2024 actual, broadly in line with the observed downward trend. Bull: 6.5% reflects partial realisation of management efficiency initiatives on a larger revenue base
C16: Operating Expenses | D16: EBITDA Margin | E16: Plug; base 23.5%, bear 23.0%, bull 24.0% | F16: Plug derived as revenue less COGS, S&A and G&A. Base case of 23.5% is in line with the 2025 outturn of 23.7% and consistent with management guidance of margins in line with 2025.
C17: Financing and Tax
C18: Financing and Tax | D18: Effective Income Tax Rate | E18: 16% - Pillar 2 full implementation | F18: Forecast at 16%, reflecting the full implementation of the OECD Pillar 2 global minimum tax rate. Historical effective rates of 12.0% (2024) and 14.0% (2025) were below 15% prior to full Pillar 2 implementation
C19: Financing and Tax | D19: Finance Income [LBO] | E19: Zero - cash swept at LBO entry | F19: Excess cash and deposits swept at LBO entry. Interest income is likely to be immaterial
C20: Financing and Tax | D20: Finance Income (% of Opening Cash) [Hold-Listed Scenario] | E20: 4.0% on opening cash - below 2-yr avg (4.98%) | F20: Interest income on cash reserves assumed at 4.0% per annum, below the 2-year historical average of 4.98% (2024: 5.60%; 2025: 4.35%), reflecting the declining interest rate environment over the forecast period
C21: Financing and Tax | D21: Lease Finance Costs | E21: 6.3% - 3-yr avg adjusted upward for IBR increases | F21: Historical average (2023-2025) of 6.15% adjusted upwards to reflect the increase in lease IBRs. 2025 rates expected to reverse partially as the Fed cuts rates. (2022: 5.21%; 2023: 5.78%; 2024: 5.95%; 2025: 6.72%)
C22: Financing and Tax | D22: Non-Lease Finance Costs | E22: Frozen at 2025 actual ($42k) - bank charges only | F22: Consists of bank charges. Bank charges frozen due to lack of identifiable drivers
C23: Working Capital
C24: Inventory | D24: Inventory Days | E24: Anchored to 2025 actual (54.6 days) | F24: Anchored to the 2025 actual of 54.6 days. Consistent with 2022 and 2024 outturns of 55.3 and 52.6 days respectively. 2023 excluded as an outlier year of apparent destocking (49.3 days)
C25: Trade and Other Receivables | D25: AR Days | E25: Anchored to 2025 actual (7.5 days) | F25: Anchored to the 2025 actual of 7.52 days. Consistent with the observed upward trend (2022: 4.3 days to 2025: 7.5 days)
C26: Trade and Other Receivables | D26: Prepaid Expenses (% of Revenue) | E26: 3-yr avg 1.61% (2023-2025); rounded to 1.5% | F26: 3-year average of 1.61% of revenue (2023: 1.64%; 2024: 1.66%; 2025: 1.52%), rounded down to 1.5% which is consistent with 2025 actuals. 2022 excluded (1.31%) as unrepresentative of the current prepaid expense base
C27: Trade and Other Receivables | D27: Advances to Suppliers | E27: Frozen at 2025 actual ($1,612k) - immaterial | F27: Held at 2025 closing balance due to lack of identifiable drivers. Will vary based on vendor negotiation. Immaterial
C28: Trade and Other Receivables | D28: Refundable Deposits | E28: Frozen at 2025 actual ($16,100k) | F28: Held at 2025 closing balance. Theoretically should grow with store count, however individual deposits will vary significantly by market and landlord. Immaterial at less than 1% of revenue
C29: Trade and Other Receivables | D29: Accrued Income (% of Revenue) | E29: 3-yr avg 0.59% (2023-2025); rounded to 0.6% | F29: 3-year average of 0.59% of revenue (2023: 0.51%; 2024: 0.63%; 2025: 0.61%), rounded to 0.6%. 2022 excluded (0.24%) as unrepresentative of the current franchise and delivery partner mix
C30: Trade and Other Receivables | D30: Insurance Receivables | E30: Frozen at 2025 actual ($410k) - immaterial | F30: Held at 2025 closing balance. Timing driven balance with no clear predictable forward driver. Immaterial
C31: Trade and Other Receivables | D31: Staff Receivables | E31: Frozen at 2025 actual ($2,553k) - immaterial | F31: Held at 2025 closing balance. Driven by HR policy. Immaterial
C32: Trade and Other Receivables | D32: VAT Receivable | E32: Frozen at 2025 actual ($4,558k) - immaterial | F32: Held at 2025 closing balance. Recovery timing varies across jurisdictions. No reliable driver given presence in multiple markets. Immaterial
C33: Trade and Other Receivables | D33: Other Receivables | E33: Frozen at 2025 actual ($8,494k) - immaterial | F33: Residuals with no single identifiable driver. Immaterial
C34: Trade and Other Receivables | D34: Non-Current Receivables Portion | E34: Frozen at $7,500k - 2023/2024 avg | F34: Data available only post 2023, frozen value reflects 2023 and 2024 levels. Spike in 2025 considered timing-driven and not structural
C35: Trade and Other Payables | D35: Trade Payables (% of Revenue) | E35: 2-yr avg 18.65% (2024: 18.75%; 2025: 18.55%) | F35: 2-year average of 18.65% of revenue (2024: 18.75%; 2025: 18.55%). Downward trend from 2022/2023 levels considered structural rather than cyclical (2022: 19.06%; 2023: 19.50%)
C36: Trade and Other Payables | D36: Non-Current Trade Payables | E36: Frozen at 2025 actual ($2,729k) - immaterial | F36: Held at 2025 closing balance. Represents unamortised supplier volume discounts deducted from inventory cost and recognised through COGS. Immaterial
C37: Fixed Assets
C38: PPE | D38: PPE Capex (% of Revenue) | E38: Scenario toggle; base 4.5%, bear 4.0%, bull 5.0% | F38: Scenario toggle. Base case of 4.5% represents the midpoint between the 2025 actual of 3.78% (113 organic NSOs) and the 4-year average of 4.74% (2022: 5.05%; 2023: 5.29%; 2024: 4.85%; 2025: 3.78%). Bear case of 4.0% anchored to the 2025 actual, reflecting a cautious expansion environment. Bull case of 5.0% consistent with the 4-year average, reflecting accelerated store rollout at 140 NSOs
C39: PPE | D39: PPE Disposals | E39: Frozen at 2025 actual ($2,691k) - immaterial | F39: Frozen, immaterial and would add unnecessary complexity to model
C40: PPE | D40: PPE Depreciation (% of Opening Balance) | E40: 4-yr avg 25.9% (2022-2025); rounded to 26.0% | F40: 4-year average of 25.9% of opening PPE balance (2022: 26.7%; 2023: 25.6%; 2024: 24.9%; 2025: 26.4%). Rounded to 26.0%.
C41: PPE | D41: PPE Other Adjustments | E41: Zero - hyperinflation/FX, non-operating | F41: Due to Hyperinflation and Forex movements which are of a non-operating nature. Assumed to be zero
C42: RoU Assets | D42: RoU Addition per NSO | E42: 2-yr avg $2,031k/store; rounded to $2,000k | F42: 2-year average of $2,031k per organic NSO (2024: $1,803k; 2025: $2,258k), rounded to $2,000k. 2022/2023 excluded (2022: $1,344k; 2023: $1,069k) as unrepresentative, reflecting a lower IBR and rental cost environment
C43: RoU Assets | D43: RoU Depreciation (% of Opening Balance) | E43: 2-yr avg 36.59% (2024-2025); rounded to 36.0% | F43: 2-year average of 36.59% of opening RoU NBV (2024: 36.87%; 2025: 36.32%), rounded to 36.0%. 2022/2023 excluded (2022: 42.20%; 2023: 41.36%) as unrepresentative, reflecting a portfolio with shorter average remaining lease terms
...

Sheet WACC Working
B2: 1 - Segment revenues (2025)
B3: Segment | C3: Revenue
B4: Major GCC | C4: 1821532
B5: Lower GCC | C5: 225978
B6: Northern Africa | C6: 223236
B7: Others | C7: 238075
B8: Total | C8: =SUM(C4:C7) -> 2508821
B10: 2 - Revenue Allocation using store counts as proxy
B11: Country | C11: Stores | D11: Weighted Revenue | E11: Region
B12: UAE | C12: 652 | D12: =(C12/SUM($C$12:$C$14))*$C$4 -> 701085.52 | E12: Major GCC
B13: KSA | C13: 766 | D13: =(C13/SUM($C$12:$C$14))*$C$4 -> 823667.95 | E13: Major GCC
B14: Kuwait | C14: 276 | D14: =(C14/SUM($C$12:$C$14))*$C$4 -> 296778.53 | E14: Major GCC
B15: Oman | C15: 101 | D15: =(C15/SUM($C$15:$C$17))*$C$5 -> 79525.359 | E15: Lower GCC
B16: Bahrain | C16: 77 | D16: =(C16/SUM($C$15:$C$17))*$C$5 -> 60628.244 | E16: Lower GCC
B17: Qatar | C17: 109 | D17: =(C17/SUM($C$15:$C$17))*$C$5 -> 85824.397 | E17: Lower GCC
B18: Egypt | C18: 450 | D18: =(C18/SUM($C$18:$C$19))*$C$6 -> 198923.17 | E18: Northern Africa
B19: Morocco | C19: 55 | D19: =(C19/SUM($C$18:$C$19))*$C$6 -> 24312.832 | E19: Northern Africa
B20: Lebanon | C20: 17 | D20: =(C20/SUM($C$20:$C$23))*$C$7 -> 15388.878 | E20: Others
B21: Kazakhstan | C21: 147 | D21: =(C21/SUM($C$20:$C$23))*$C$7 -> 133068.54 | E21: Others
B22: Jordan | C22: 57 | D22: =(C22/SUM($C$20:$C$23))*$C$7 -> 51598.004 | E22: Others
B23: Iraq | C23: 42 | D23: =(C23/SUM($C$20:$C$23))*$C$7 -> 38019.582 | E23: Others
B24: Total | C24: =SUM(C12:C23) -> 2749 | D24: =SUM(D12:D23) -> 2508821
B26: 3 - Blended ERP calculation
B27: Country | C27: Old ERP | D27: ERP New | E27: Blended Old ERP (ex-Leb) | F27: Blended New ERP (all) | G27: Blended New ERP (ex-Leb)
B28: UAE | C28: 4.93 | D28: 5.91 | E28: =C28*(D12/($D$24-$D$20)) -> 1.3861823 | F28: =D28*(D12/($D$24)) -> 1.6515389 | G28: =D28*(D12/($D$24-$D$20)) -> 1.6617318
B29: KSA | C29: 5.72 | D29: 6.46 | E29: =C29*(D13/($D$24-$D$20)) -> 1.8895163 | F29: =D29*(D13/($D$24)) -> 2.1208747 | G29: =D29*(D13/($D$24-$D$20)) -> 2.1339642
B30: Kuwait | C30: 5.34 | D30: 6.09 | E30: =C30*(D14/($D$24-$D$20)) -> 0.63558873 | F30: =D30*(D14/($D$24)) -> 0.72041061 | G30: =D30*(D14/($D$24-$D$20)) -> 0.72485681
B31: Oman | C31: 6 | D31: 6.92 | E31: =C31*(D15/($D$24-$D$20)) -> 0.1913636 | F31: =D31*(D15/($D$24)) -> 0.21935223 | G31: =D31*(D15/($D$24-$D$20)) -> 0.22070602
B32: Bahrain | C32: 7.78 | D32: 9.91 | E32: =C32*(D16/($D$24-$D$20)) -> 0.18917208 | F32: =D32*(D16/($D$24)) -> 0.23948536 | G32: =D32*(D16/($D$24-$D$20)) -> 0.24096341
B33: Qatar | C33: 4.95 | D33: 5.89 | E33: =C33*(D17/($D$24-$D$20)) -> 0.17037992 | F33: =D33*(D17/($D$24)) -> 0.20149134 | G33: =D33*(D17/($D$24-$D$20)) -> 0.2027349
B34: Egypt | C34: 9.42 | D34: 12.41 | E34: =C34*(D18/($D$24-$D$20)) -> 0.75151685 | F34: =D34*(D18/($D$24)) -> 0.98398272 | G34: =D34*(D18/($D$24-$D$20)) -> 0.99005563
B35: Morocco | C35: 6 | D35: 6.96 | E35: =C35*(D19/($D$24-$D$20)) -> 0.058504496 | F35: =D35*(D19/($D$24)) -> 0.067448937 | G35: =D35*(D19/($D$24-$D$20)) -> 0.067865216
B36: Lebanon | C36: 30.89 | D36: 31.62 | E36: 0 | F36: =D36*(D20/($D$24)) -> 0.19395419 | G36: 0
B37: Kazakhstan | C37: 6.01 | D37: 7.01 | E37: =C37*(D21/($D$24-$D$20)) -> 0.32073939 | F37: =D37*(D21/($D$24)) -> 0.37181227 | G37: =D37*(D21/($D$24-$D$20)) -> 0.37410701
B38: Jordan | C38: 8.89 | D38: 10.02 | E38: =C38*(D22/($D$24-$D$20)) -> 0.18396581 | F38: =D38*(D22/($D$24)) -> 0.20607767 | G38: =D38*(D22/($D$24-$D$20)) -> 0.20734954
B39: Iraq | C39: 8.42 | D39: 13.53 | E39: =C39*(D23/($D$24-$D$20)) -> 0.12838724 | F39: =D39*(D23/($D$24)) -> 0.20503852 | G39: =D39*(D23/($D$24-$D$20)) -> 0.20630397
B40: Total / Blended | E40: =SUM(E28:E39) -> 5.9053168 | F40: =SUM(F28:F39) -> 7.1814674 | G40: =SUM(G28:G39) -> 7.0306385
B42: 4 - Exit multiple iteration
B43: Scenario | C43: EV | D43: Equity | E43: D/E | F43: Levered β | G43: D/(D+E) | H43: Kd (wtd) | I43: Ke | J43: Ke (wtd) | K43: WACC | L43: Exit Multiple
B44: Base (Old ERPs) | C44: 8260.66 | D44: =C44-681 -> 7579.66 | E44: =681/D44 -> 0.089845719 | F44: =0.7*(1+((1-0.16)*E44)) -> 0.75282928 | G44: =681/C44 -> 0.082438933 | H44: =6.3%*G44*0.84 -> 0.0043626684 | I44: =4.1%+(F44*E40/100) -> 0.085456954 | J44: =I44*(1-G44) -> 0.078411974 | K44: =J44+H44 -> 0.082774642 | L44: =0.45/((K44)-0.035) -> 9.4192228
...
